Workbook
Name POSE_CSKN: Configurations!$K$5:$M$13

Sheet POINTAGES
A1: POINTAGES BRUT | G1: POINTAGES CONVERTITS EN JOURS
A2: Matricule | B2: DatePointage | C2: IDPointage | D2: IDPose | G2: Matricule | H2: 86567 | I2: 129091 | J2: 121678 | K2: 126547 | L2: 123939 | M2: 129152
A3: 86567 | B3: 45494 | C3: 03 | G3: JOuvrable | H3: 25 | I3: 24 | J3: 21 | K3: 20 | L3: 21 | M3: 24
A4: 86567 | B4: 45495 | C4: 98 | G4: JReposPaye | H4: 0 | I4: 1 | J4: 4 | K4: 5 | L4: 4 | M4: 1
A5: 86567 | B5: 45496 | C5: 98 | G5: JCongeCirconstance | H5: 0 | I5: 0 | J5: 0 | K5: 0 | L5: 0 | M5: 0
A6: 86567 | B6: 45497 | C6: 98 | G6: JMaladie | H6: 0 | I6: 0 | J6: 0 | K6: 0 | L6: 0 | M6: 0
A7: 86567 | B7: 45498 | C7: 98 | G7: JHospitalisation | H7: 0 | I7: 0 | J7: 0 | K7: 0 | L7: 0 | M7: 0
A8: 86567 | B8: 45499 | C8: 98 | G8: JCongeMaternite | H8: 0 | I8: 0 | J8: 0 | K8: 0 | L8: 0 | M8: 0
A9: 86567 | B9: 45500 | C9: 98 | G9: JCongeAutorise | H9: 0 | I9: 0 | J9: 0 | K9: 0 | L9: 0 | M9: 0
A10: 86567 | B10: 45501 | C10: 03 | G10: JDimanche | H10: 0 | I10: 2 | J10: 5 | K10: 5 | L10: 5 | M10: 5
A11: 86567 | B11: 45502 | C11: 98 | G11: JFeriePreste | H11: 0 | I11: 1 | J11: 1 | K11: 1 | L11: 1 | M11: 1
A12: 86567 | B12: 45503 | C12: 98 | G12: JFerieNonPreste | H12: 1 | I12: 0 | J12: 0 | K12: 0 | L12: 0 | M12: 0
A13: 86567 | B13: 45504 | C13: 98 | G13: ComplementJFDim | H13: 0 | I13: 0 | J13: 0 | K13: 0 | L13: 1 | M13: 3
A14: 86567 | B14: 45505 | C14: 11 | G14: ComplementPose2 | H14: 0 | I14: 0 | J14: 6 | K14: 6 | L14: 0 | M14: 0
... A23: 86567 | B23: 45514 | C23: 98 | G23: JMiseApied | H23: 0 | I23: 0 | J23: 0 | K23: 0 | L23: 0 | M23: 0
A24: 86567 | B24: 45515 | C24: 03 | G24: NbreHS35 | L24: 0 | M24: 0
A25: 86567 | B25: 45516 | C25: 98 | G25: NbreHS37_5 | L25: 48 | M25: 62
A26: 86567 | B26: 45517 | C26: 98 | G26: NbreHS100 | L26: 0 | M26: 0
A27: 86567 | B27: 45518 | C27: 98 | G27: NbreHS130 | L27: 24 | M27: 30
A28: 86567 | B28: 45519 | C28: 98 | G28: NbreHS160 | L28: 60 | M28: 76
A29: 86567 | B29: 45520 | C29: 98 | G29: NbreHS200 | L29: 18 | M29: 20
A30: 86567 | B30: 45521 | C30: 98
A31: 86567 | B31: 45522 | C31: 03
A32: 86567 | B32: 45523 | C32: 98
A33: 86567 | B33: 45524 | C33: 98
A34: 129091 | B34: 45494 | C34: 03
A35: 129091 | B35: 45495 | C35: 98
A36: 129091 | B36: 45496 | C36: 98
A37: 129091 | B37: 45497 | C37: 98
A38: 129091 | B38: 45498 | C38: 98
A39: 129091 | B39: 45499 | C39: 98
A40: 129091 | B40: 45500 | C40: 98
A41: 129091 | B41: 45501 | C41: 98
... A64: 129091 | B64: 45524 | C64: 98
A65: 121678 | B65: 45494 | C65: 99 | D65: 3
A66: 121678 | B66: 45495 | C66: 99 | D66: 3
A67: 121678 | B67: 45496 | C67: 99 | D67: 3
A68: 121678 | B68: 45497 | C68: 99 | D68: 2
A69: 121678 | B69: 45498 | C69: 12
A70: 121678 | B70: 45499 | C70: 99 | D70: 2
...

Sheet HS
B2: Matricule | C2: 123939 | D2: 129152
B3: NbreHS35 | C3: 0 | D3: 0
B4: NbreHS37_5 | C4: 48 | D4: 62
B5: NbreHS100 | C5: 0 | D5: 0
B6: NbreHS130 | C6: 24 | D6: 30
B7: NbreHS160 | C7: 60 | D7: 76
B8: NbreHS200 | C8: 18 | D8: 20

Sheet CODE_POINTAGE
B2: CODE DES POINTAGES | H2: CODE DES POINTAGES
B4: CODE | C4: LIBELLE | D4: TACHE | E4: PRESENCE | H4: CODE | I4: LIBELLE
B5: 01 | C5: ABSENCE AUTORISEE NON A PAYER | D5: 0 | E5: 0 | H5: 0 | I5: EQUIPE JOUR
B6: 02 | C6: ABSENCE NON AUTORISEE | D6: 0 | E6: 0 | H6: 1 | I6: POSE 1 DE 8 H (6 - 14 OU 7-15)
B7: 03 | C7: SANS POINTAGE | D7: 0 | E7: 0 | H7: 2 | I7: POSE 2 DE 8 H (14--22 OU 15-23
B8: 04 | C8: CARTE RETENUE | D8: 0 | E8: 0 | H8: 3 | I8: POSE 3 DE 8 H (22-6 OU 23-7)
B9: 05 | C9: CONGE DE CIRCONSTANCE | D9: 0 | E9: 0 | H9: 6 | I9: POSE 1 DE 12H ( 6-18)
B10: 06 | C10: SUSPENSION/CONVOCATION | D10: 0 | E10: 0 | H10: 7 | I10: CHANGEMENT DE POSE 6-18 / 18-6
B11: 07 | C11: ACCID. TRAV./INCAPACITE CADRE | D11: 0 | E11: 0 | H11: 8 | I11: POSE 2 DE 12H (18-6)
B12: 08 | C12: MALADIE/REPOS MEDICAL/MATERNITE | D12: 0 | E12: 0 | H12: N | I12: NON POSE
B13: 09 | C13: SANCTION | D13: 0 | E13: 0
B14: 10 | C14: SUSPENSION CONTRAT | D14: 0 | E14: 0
B15: 11 | C15: JOURNEE FERIEE NON PRESTEE | D15: 0 | E15: 0
B16: 12 | C16: REPOS PAYE | D16: 0 | E16: 0
B17: 13 | C17: GARDE A DOMICILE | D17: 0 | E17: 0
B18: 14 | C18: POINTAGE EXCEPTIONNELLE | D18: 0 | E18: 0
B19: 15 | C19: CESSATION DE TRAVAIL | D19: 0 | E19: 0
B20: 20 | C20: COUPE FABRICATION | D20: 1 | E20: 1
B21: 21 | C21: COUPE-FEU RECOLTE | D21: 1 | E21: 1
B22: 22 | C22: COUPE DEGAGEMENT | D22: 1 | E22: 1
B23: 23 | C23: COUPE-FEU EXTERIEUR | D23: 1 | E23: 1
B24: 24 | C24: GLANAGE MACHINE | D24: 0 | E24: 1
... B99: 99 | C99: AUTRES TRAVAUX EXTERIEURS | D99: 0 | E99: 1

Sheet Feuil1
B2: Matricule | C2: 123939
C4: Jour | D4: Date | E4: Pose | F4: durée | G4: HS | J4: Debut | K4: Durée | S4: Pose | T4: Debut | U4: Durée | V4: _200
C5: =TEXT(D5,"jjjj") -> dimanche | D5: 45494 | E5: 998 | F5: 12 | G5: =IF(F5-IF(C5="samedi",5,8)<0,0,F5-IF(C5="samedi",5,8)) -> 4 | J5: 18 - 6 | K5: 12 | O5: 129152 | P5: 45494 | Q5: =TEXT(P5,"jjjj") -> dimanche | R5: 99 | S5: 6
C6: =TEXT(D6,"jjjj") -> lundi | D6: 45495 | E6: 997 | F6: 18 | G6: =IF(F6-IF(C6="samedi",5,8)<0,0,F6-IF(C6="samedi",5,8)) -> 10 | J6: 12 - 6 | K6: 18 | O6: 129152 | P6: 45495 | Q6: =TEXT(P6,"jjjj") -> lundi | R6: 99 | S6: 7
C7: =TEXT(D7,"jjjj") -> mardi | D7: 45496 | E7: 12 | F7: 0 | G7: =IF(F7-IF(C7="samedi",5,8)<0,0,F7-IF(C7="samedi",5,8)) -> 0 | O7: 129152 | P7: 45496 | Q7: =TEXT(P7,"jjjj") -> mardi | R7: 99 | S7: 8
C8: =TEXT(D8,"jjjj") -> mercredi | D8: 45497 | E8: 996 | F8: 12 | G8: =IF(F8-IF(C8="samedi",5,8)<0,0,F8-IF(C8="samedi",5,8)) -> 4 | J8: 6 - 18 | K8: 12 | O8: 129152 | P8: 45497 | Q8: =TEXT(P8,"jjjj") -> mercredi | R8: 99 | S8: 8
C9: =TEXT(D9,"jjjj") -> jeudi | D9: 45498 | E9: 996 | F9: 12 | G9: =IF(F9-IF(C9="samedi",5,8)<0,0,F9-IF(C9="samedi",5,8)) -> 4 | J9: 6 - 18 | K9: 12 | O9: 129152 | P9: 45498 | Q9: =TEXT(P9,"jjjj") -> jeudi | R9: 99 | S9: 8
C10: =TEXT(D10,"jjjj") -> vendredi | D10: 45499 | E10: 996 | F10: 12 | G10: =IF(F10-IF(C10="samedi",5,8)<0,0,F10-IF(C10="samedi",5,8)) -> 4 | J10: 6 - 18 | K10: 12 | O10: 129152 | P10: 45499 | Q10: =TEXT(P10,"jjjj") -> vendredi | R10: 99 | S10: 8
C11: =TEXT(D11,"jjjj") -> samedi | D11: 45500 | E11: 996 | F11: 12 | G11: =IF(F11-IF(C11="samedi",5,8)<0,0,F11-IF(C11="samedi",5,8)) -> 7 | J11: 6 - 18 | K11: 12 | O11: 129152 | P11: 45500 | Q11: =TEXT(P11,"jjjj") -> samedi | R11: 99 | S11: 8
C12: =TEXT(D12,"jjjj") -> dimanche | D12: 45501 | E12: 996 | F12: 12 | G12: =IF(F12-IF(C12="samedi",5,8)<0,0,F12-IF(C12="samedi",5,8)) -> 4 | J12: 6 - 18 | K12: 12 | O12: 129152 | P12: 45501 | Q12: =TEXT(P12,"jjjj") -> dimanche | R12: 99 | S12: 8
C13: =TEXT(D13,"jjjj") -> lundi | D13: 45502 | E13: 997 | F13: 18 | G13: =IF(F13-IF(C13="samedi",5,8)<0,0,F13-IF(C13="samedi",5,8)) -> 10 | J13: 12 - 6 | K13: 18 | O13: 129152 | P13: 45502 | Q13: =TEXT(P13,"jjjj") -> lundi | R13: 99 | S13: 7
C14: =TEXT(D14,"jjjj") -> mardi | D14: 45503 | E14: 998 | F14: 12 | G14: =IF(F14-IF(C14="samedi",5,8)<0,0,F14-IF(C14="samedi",5,8)) -> 4 | J14: 18 - 6 | K14: 12 | O14: 129152 | P14: 45503 | Q14: =TEXT(P14,"jjjj") -> mardi | R14: 99 | S14: 6
C15: =TEXT(D15,"jjjj") -> mercredi | D15: 45504 | E15: 998 | F15: 12 | G15: =IF(F15-IF(C15="samedi",5,8)<0,0,F15-IF(C15="samedi",5,8)) -> 4 | J15: 18 - 6 | K15: 12 | O15: 129152 | P15: 45504 | Q15: =TEXT(P15,"jjjj") -> mercredi | R15: 99 | S15: 6
C16: =TEXT(D16,"jjjj") -> jeudi | D16: 45505 | E16: 998 | F16: 12 | G16: =IF(F16-IF(C16="samedi",5,8)<0,0,F16-IF(C16="samedi",5,8)) -> 4 | J16: 18 - 6 | K16: 12 | O16: 129152 | P16: 45505 | Q16: =TEXT(P16,"jjjj") -> jeudi | R16: 99 | S16: 6
C17: =TEXT(D17,"jjjj") -> vendredi | D17: 45506 | E17: 998 | F17: 12 | G17: =IF(F17-IF(C17="samedi",5,8)<0,0,F17-IF(C17="samedi",5,8)) -> 4 | J17: 18 - 6 | K17: 12 | O17: 129152 | P17: 45506 | Q17: =TEXT(P17,"jjjj") -> vendredi | R17: 12
C18: =TEXT(D18,"jjjj") -> samedi | D18: 45507 | E18: 998 | F18: 12 | G18: =IF(F18-IF(C18="samedi",5,8)<0,0,F18-IF(C18="samedi",5,8)) -> 7 | J18: 18 - 6 | K18: 12 | O18: 129152 | P18: 45507 | Q18: =TEXT(P18,"jjjj") -> samedi | R18: 99 | S18: 6
C19: =TEXT(D19,"jjjj") -> dimanche | D19: 45508 | E19: 998 | F19: 12 | G19: =IF(F19-IF(C19="samedi",5,8)<0,0,F19-IF(C19="samedi",5,8)) -> 4 | J19: 18 - 6 | K19: 12 | O19: 129152 | P19: 45508 | Q19: =TEXT(P19,"jjjj") -> dimanche | R19: 99 | S19: 6
C20: =TEXT(D20,"jjjj") -> lundi | D20: 45509 | E20: 997 | F20: 18 | G20: =IF(F20-IF(C20="samedi",5,8)<0,0,F20-IF(C20="samedi",5,8)) -> 10 | J20: 12 - 6 | K20: 18 | O20: 129152 | P20: 45509 | Q20: =TEXT(P20,"jjjj") -> lundi | R20: 99 | S20: 7
C21: =TEXT(D21,"jjjj") -> mardi | D21: 45510 | E21: 12 | F21: 0 | G21: =IF(F21-IF(C21="samedi",5,8)<0,0,F21-IF(C21="samedi",5,8)) -> 0 | O21: 129152 | P21: 45510 | Q21: =TEXT(P21,"jjjj") -> mardi | R21: 99 | S21: 8
C22: =TEXT(D22,"jjjj") -> mercredi | D22: 45511 | E22: 996 | F22: 12 | G22: =IF(F22-IF(C22="samedi",5,8)<0,0,F22-IF(C22="samedi",5,8)) -> 4 | J22: 6 - 18 | K22: 12 | O22: 129152 | P22: 45511 | Q22: =TEXT(P22,"jjjj") -> mercredi | R22: 99 | S22: 8
C23: =TEXT(D23,"jjjj") -> jeudi | D23: 45512 | E23: 996 | F23: 12 | G23: =IF(F23-IF(C23="samedi",5,8)<0,0,F23-IF(C23="samedi",5,8)) -> 4 | J23: 6 - 18 | K23: 12 | O23: 129152 | P23: 45512 | Q23: =TEXT(P23,"jjjj") -> jeudi | R23: 99 | S23: 8
C24: =TEXT(D24,"jjjj") -> vendredi | D24: 45513 | E24: 996 | F24: 12 | G24: =IF(F24-IF(C24="samedi",5,8)<0,0,F24-IF(C24="samedi",5,8)) -> 4 | J24: 6 - 18 | K24: 12 | O24: 129152 | P24: 45513 | Q24: =TEXT(P24,"jjjj") -> vendredi | R24: 99 | S24: 8
C25: =TEXT(D25,"jjjj") -> samedi | D25: 45514 | E25: 996 | F25: 12 | G25: =IF(F25-IF(C25="samedi",5,8)<0,0,F25-IF(C25="samedi",5,8)) -> 7 | J25: 6 - 18 | K25: 12 | O25: 129152 | P25: 45514 | Q25: =TEXT(P25,"jjjj") -> samedi | R25: 99 | S25: 8
C26: =TEXT(D26,"jjjj") -> dimanche | D26: 45515 | E26: 996 | F26: 12 | G26: =IF(F26-IF(C26="samedi",5,8)<0,0,F26-IF(C26="samedi",5,8)) -> 4 | J26: 6 - 18 | K26: 12 | O26: 129152 | P26: 45515 | Q26: =TEXT(P26,"jjjj") -> dimanche | R26: 99 | S26: 8
C27: =TEXT(D27,"jjjj") -> lundi | D27: 45516 | E27: 997 | F27: 18 | G27: =IF(F27-IF(C27="samedi",5,8)<0,0,F27-IF(C27="samedi",5,8)) -> 10 | J27: 12 - 6 | K27: 18 | O27: 129152 | P27: 45516 | Q27: =TEXT(P27,"jjjj") -> lundi | R27: 99 | S27: 7
C28: =TEXT(D28,"jjjj") -> mardi | D28: 45517 | E28: 998 | F28: 12 | G28: =IF(F28-IF(C28="samedi",5,8)<0,0,F28-IF(C28="samedi",5,8)) -> 4 | J28: 18 - 6 | K28: 12 | O28: 129152 | P28: 45517 | Q28: =TEXT(P28,"jjjj") -> mardi | R28: 99 | S28: 6
C29: =TEXT(D29,"jjjj") -> mercredi | D29: 45518 | E29: 998 | F29: 12 | G29: =IF(F29-IF(C29="samedi",5,8)<0,0,F29-IF(C29="samedi",5,8)) -> 4 | J29: 18 - 6 | K29: 12 | O29: 129152 | P29: 45518 | Q29: =TEXT(P29,"jjjj") -> mercredi | R29: 99 | S29: 6
C30: =TEXT(D30,"jjjj") -> jeudi | D30: 45519 | E30: 998 | F30: 12 | G30: =IF(F30-IF(C30="samedi",5,8)<0,0,F30-IF(C30="samedi",5,8)) -> 4 | J30: 18 - 6 | K30: 12 | O30: 129152 | P30: 45519 | Q30: =TEXT(P30,"jjjj") -> jeudi | R30: 99 | S30: 6
C31: =TEXT(D31,"jjjj") -> vendredi | D31: 45520 | E31: 998 | F31: 12 | G31: =IF(F31-IF(C31="samedi",5,8)<0,0,F31-IF(C31="samedi",5,8)) -> 4 | J31: 18 - 6 | K31: 12 | O31: 129152 | P31: 45520 | Q31: =TEXT(P31,"jjjj") -> vendredi | R31: 99 | S31: 6
C32: =TEXT(D32,"jjjj") -> samedi | D32: 45521 | E32: 12 | F32: 0 | G32: =IF(F32-IF(C32="samedi",5,8)<0,0,F32-IF(C32="samedi",5,8)) -> 0 | O32: 129152 | P32: 45521 | Q32: =TEXT(P32,"jjjj") -> samedi | R32: 99 | S32: 6
C33: =TEXT(D33,"jjjj") -> dimanche | D33: 45522 | E33: 998 | F33: 12 | G33: =IF(F33-IF(C33="samedi",5,8)<0,0,F33-IF(C33="samedi",5,8)) -> 4 | J33: 18 - 6 | K33: 12 | O33: 129152 | P33: 45522 | Q33: =TEXT(P33,"jjjj") -> dimanche | R33: 99 | S33: 6
C34: =TEXT(D34,"jjjj") -> lundi | D34: 45523 | E34: 997 | F34: 18 | G34: =IF(F34-IF(C34="samedi",5,8)<0,0,F34-IF(C34="samedi",5,8)) -> 10 | J34: 12 - 6 | K34: 18 | O34: 129152 | P34: 45523 | Q34: =TEXT(P34,"jjjj") -> lundi | R34: 99 | S34: 7
C35: =TEXT(D35,"jjjj") -> mardi | D35: 45524 | E35: 12 | F35: 0 | G35: =IF(F35-IF(C35="samedi",5,8)<0,0,F35-IF(C35="samedi",5,8)) -> 0 | O35: 129152 | P35: 45524 | Q35: =TEXT(P35,"jjjj") -> mardi | R35: 99 | S35: 8
C39: Forme du résulat attendu
D41: prestation | E41: 1.3 | F41: 1.6 | G41: 2
C42: semaine 1 | D42: 66 sur 45 | E42: 6 | F42: 15 | G42: 0
C43: semaine 2 | D43: 70 sur 37 | E43: 6 | F43: 27 | G43: 0
C44: semaine 3 | D44: 66 sur 45 | E44: 6 | F44: 15 | G44: 0
C45: semaine 4 | D45: 66 sur 45 | E45: 6 | F45: 15 | G45: 0
C46: semaine 5 | D46: 18 sur 8 | E46: 6 | F46: 4 | G46: 0
...

Sheet Feuil2
B2: Jour | C2: Date | D2: Pose | E2: Durée prestation | F2: HS Jr ouvré | G2: HS Jr non ouvré | M2: Date | N2: Jour
B3: =TEXT(C3,"jjjj") -> dimanche | C3: 45494 | D3: 998 | E3: =IF(LEN(TRIM(D3))=2,VLOOKUP(TEXT(D3,"00"),Configurations!$B$5:$G$100,6,0),VLOOKUP(TEXT(RIGHT(D3,1),"0"),POSE_CSKN,3,0)) -> 12 | F3: =IF(OR(WEEKDAY(C3)>1, COUNTIF(Tableau_Pose_Cskn[Date],C3)=0),IF(E3>0,E3-IF(WEEKDAY(C3)=7,5,8),0),0) -> 4 | G3: =IF(OR(WEEKDAY(C3)=1, COUNTIF(Tableau_Pose_Cskn[Date],C3)>0),IF(E3>0,E3-IF(WEEKDAY(C3)=7,5,8),0),0) -> 4 | M3: 45505 | N3: Férié
B4: =TEXT(C4,"jjjj") -> lundi | C4: 45495 | D4: 997 | E4: =IF(LEN(TRIM(D4))=2,VLOOKUP(TEXT(D4,"00"),Configurations!$B$5:$G$100,6,0),VLOOKUP(TEXT(RIGHT(D4,1),"0"),POSE_CSKN,3,0)) -> 18 | F4: =IF(OR(WEEKDAY(C4)<>1, COUNTIF(Tableau_Pose_Cskn[Date],C4)=0),IF(E4>0,E4-IF(WEEKDAY(C4)=7,5,8),0),0) -> 10 | G4: =IF(OR(WEEKDAY(C4)=1, COUNTIF(Tableau_Pose_Cskn[Date],C4)>0),IF(E4>0,E4-IF(WEEKDAY(C4)=7,5,8),0),0) -> 0 | M4: 45651 | N4: Noel
B5: =TEXT(C5,"jjjj") -> mardi | C5: 45496 | D5: 12 | E5: =IF(LEN(TRIM(D5))=2,VLOOKUP(TEXT(D5,"00"),Configurations!$B$5:$G$100,6,0),VLOOKUP(TEXT(RIGHT(D5,1),"0"),POSE_CSKN,3,0)) -> 0 | F5: =IF(OR(WEEKDAY(C5)<>1, COUNTIF(Tableau_Pose_Cskn[Date],C5)=0),IF(E5>0,E5-IF(WEEKDAY(C5)=7,5,8),0),0) -> 0 | G5: =IF(OR(WEEKDAY(C5)=1, COUNTIF(Tableau_Pose_Cskn[Date],C5)>0),IF(E5>0,E5-IF(WEEKDAY(C5)=7,5,8),0),0) -> 0
B6: =TEXT(C6,"jjjj") -> mercredi | C6: 45497 | D6: 996 | E6: =IF(LEN(TRIM(D6))=2,VLOOKUP(TEXT(D6,"00"),Configurations!$B$5:$G$100,6,0),VLOOKUP(TEXT(RIGHT(D6,1),"0"),POSE_CSKN,3,0)) -> 12 | F6: =IF(OR(WEEKDAY(C6)<>1, COUNTIF(Tableau_Pose_Cskn[Date],C6)=0),IF(E6>0,E6-IF(WEEKDAY(C6)=7,5,8),0),0) -> 4 | G6: =IF(OR(WEEKDAY(C6)=1, COUNTIF(Tableau_Pose_Cskn[Date],C6)>0),IF(E6>0,E6-IF(WEEKDAY(C6)=7,5,8),0),0) -> 0 | K6: 45505
B7: =TEXT(C7,"jjjj") -> jeudi | C7: 45498 | D7: 996 | E7: =IF(LEN(TRIM(D7))=2,VLOOKUP(TEXT(D7,"00"),Configurations!$B$5:$G$100,6,0),VLOOKUP(TEXT(RIGHT(D7,1),"0"),POSE_CSKN,3,0)) -> 12 | F7: =IF(OR(WEEKDAY(C7)<>1, COUNTIF(Tableau_Pose_Cskn[Date],C7)=0),IF(E7>0,E7-IF(WEEKDAY(C7)=7,5,8),0),0) -> 4 | G7: =IF(OR(WEEKDAY(C7)=1, COUNTIF(Tableau_Pose_Cskn[Date],C7)>0),IF(E7>0,E7-IF(WEEKDAY(C7)=7,5,8),0),0) -> 0
B8: =TEXT(C8,"jjjj") -> vendredi | C8: 45499 | D8: 996 | E8: =IF(LEN(TRIM(D8))=2,VLOOKUP(TEXT(D8,"00"),Configurations!$B$5:$G$100,6,0),VLOOKUP(TEXT(RIGHT(D8,1),"0"),POSE_CSKN,3,0)) -> 12 | F8: =IF(OR(WEEKDAY(C8)<>1, COUNTIF(Tableau_Pose_Cskn[Date],C8)=0),IF(E8>0,E8-IF(WEEKDAY(C8)=7,5,8),0),0) -> 4 | G8: =IF(OR(WEEKDAY(C8)=1, COUNTIF(Tableau_Pose_Cskn[Date],C8)>0),IF(E8>0,E8-IF(WEEKDAY(C8)=7,5,8),0),0) -> 0
B9: =TEXT(C9,"jjjj") -> samedi | C9: 45500 | D9: 996 | E9: =IF(LEN(TRIM(D9))=2,VLOOKUP(TEXT(D9,"00"),Configurations!$B$5:$G$100,6,0),VLOOKUP(TEXT(RIGHT(D9,1),"0"),POSE_CSKN,3,0)) -> 12 | F9: =IF(OR(WEEKDAY(C9)<>1, COUNTIF(Tableau_Pose_Cskn[Date],C9)=0),IF(E9>0,E9-IF(WEEKDAY(C9)=7,5,8),0),0) -> 7 | G9: =IF(OR(WEEKDAY(C9)=1, COUNTIF(Tableau_Pose_Cskn[Date],C9)>0),IF(E9>0,E9-IF(WEEKDAY(C9)=7,5,8),0),0) -> 0
B10: =TEXT(C10,"jjjj") -> dimanche | C10: 45501 | D10: 996 | E10: =IF(LEN(TRIM(D10))=2,VLOOKUP(TEXT(D10,"00"),Configurations!$B$5:$G$100,6,0),VLOOKUP(TEXT(RIGHT(D10,1),"0"),POSE_CSKN,3,0)) -> 12 | F10: =IF(OR(WEEKDAY(C10)<>1, COUNTIF(Tableau_Pose_Cskn[Date],C10)=0),IF(E10>0,E10-IF(WEEKDAY(C10)=7,5,8),0),0) -> 4 | G10: =IF(OR(WEEKDAY(C10)=1, COUNTIF(Tableau_Pose_Cskn[Date],C10)>0),IF(E10>0,E10-IF(WEEKDAY(C10)=7,5,8),0),0) -> 4
B11: =TEXT(C11,"jjjj") -> lundi | C11: 45502 | D11: 997 | E11: =IF(LEN(TRIM(D11))=2,VLOOKUP(TEXT(D11,"00"),Configurations!$B$5:$G$100,6,0),VLOOKUP(TEXT(RIGHT(D11,1),"0"),POSE_CSKN,3,0)) -> 18 | F11: =IF(OR(WEEKDAY(C11)<>1, COUNTIF(Tableau_Pose_Cskn[Date],C11)=0),IF(E11>0,E11-IF(WEEKDAY(C11)=7,5,8),0),0) -> 10 | G11: =IF(OR(WEEKDAY(C11)=1, COUNTIF(Tableau_Pose_Cskn[Date],C11)>0),IF(E11>0,E11-IF(WEEKDAY(C11)=7,5,8),0),0) -> 0
B12: =TEXT(C12,"jjjj") -> mardi | C12: 45503 | D12: 998 | E12: =IF(LEN(TRIM(D12))=2,VLOOKUP(TEXT(D12,"00"),Configurations!$B$5:$G$100,6,0),VLOOKUP(TEXT(RIGHT(D12,1),"0"),POSE_CSKN,3,0)) -> 12 | F12: =IF(OR(WEEKDAY(C12)<>1, COUNTIF(Tableau_Pose_Cskn[Date],C12)=0),IF(E12>0,E12-IF(WEEKDAY(C12)=7,5,8),0),0) -> 4 | G12: =IF(OR(WEEKDAY(C12)=1, COUNTIF(Tableau_Pose_Cskn[Date],C12)>0),IF(E12>0,E12-IF(WEEKDAY(C12)=7,5,8),0),0) -> 0 | L12: =COUNTIF(Tableau_Pose_Cskn[Date],C14)=0 -> FALSE
B13: =TEXT(C13,"jjjj") -> mercredi | C13: 45504 | D13: 998 | E13: =IF(LEN(TRIM(D13))=2,VLOOKUP(TEXT(D13,"00"),Configurations!$B$5:$G$100,6,0),VLOOKUP(TEXT(RIGHT(D13,1),"0"),POSE_CSKN,3,0)) -> 12 | F13: =IF(OR(WEEKDAY(C13)<>1, COUNTIF(Tableau_Pose_Cskn[Date],C13)=0),IF(E13>0,E13-IF(WEEKDAY(C13)=7,5,8),0),0) -> 4 | G13: =IF(OR(WEEKDAY(C13)=1, COUNTIF(Tableau_Pose_Cskn[Date],C13)>0),IF(E13>0,E13-IF(WEEKDAY(C13)=7,5,8),0),0) -> 0
B14: =TEXT(C14,"jjjj") -> jeudi | C14: 45505 | D14: 998 | E14: =IF(LEN(TRIM(D14))=2,VLOOKUP(TEXT(D14,"00"),Configurations!$B$5:$G$100,6,0),VLOOKUP(TEXT(RIGHT(D14,1),"0"),POSE_CSKN,3,0)) -> 12 | F14: =IF(OR(WEEKDAY(C14)<>1, COUNTIF(Tableau_Pose_Cskn[Date],C14)=0),IF(E14>0,E14-IF(WEEKDAY(C14)=7,5,8),0),0) -> 4 | G14: =IF(OR(WEEKDAY(C14)=1, COUNTIF(Tableau_Pose_Cskn[Date],C14)>0),IF(E14>0,E14-IF(WEEKDAY(C14)=7,5,8),0),0) -> 4
B15: =TEXT(C15,"jjjj") -> vendredi | C15: 45506 | D15: 998 | E15: =IF(LEN(TRIM(D15))=2,VLOOKUP(TEXT(D15,"00"),Configurations!$B$5:$G$100,6,0),VLOOKUP(TEXT(RIGHT(D15,1),"0"),POSE_CSKN,3,0)) -> 12 | F15: =IF(WEEKDAY(C15)<>1,IF(E15>0,E15-IF(WEEKDAY(C15)=7,5,8),0),0) -> 4 | G15: =IF(OR(WEEKDAY(C15)=1, COUNTIF(Tableau_Pose_Cskn[Date],C15)>0),IF(E15>0,E15-IF(WEEKDAY(C15)=7,5,8),0),0) -> 0 | L15: =OR(WEEKDAY(C3)>1, COUNTIF(Tableau_Pose_Cskn[Date],C3)=0) -> TRUE | N15: =COUNTIF(Tableau_Pose_Cskn[Date],C3)=0 -> TRUE
B16: =TEXT(C16,"jjjj") -> samedi | C16: 45507 | D16: 998 | E16: =IF(LEN(TRIM(D16))=2,VLOOKUP(TEXT(D16,"00"),Configurations!$B$5:$G$100,6,0),VLOOKUP(TEXT(RIGHT(D16,1),"0"),POSE_CSKN,3,0)) -> 12 | F16: =IF(WEEKDAY(C16)<>1,IF(E16>0,E16-IF(WEEKDAY(C16)=7,5,8),0),0) -> 7 | G16: =IF(OR(WEEKDAY(C16)=1, COUNTIF(Tableau_Pose_Cskn[Date],C16)>0),IF(E16>0,E16-IF(WEEKDAY(C16)=7,5,8),0),0) -> 0
B17: =TEXT(C17,"jjjj") -> dimanche | C17: 45508 | D17: 998 | E17: =IF(LEN(TRIM(D17))=2,VLOOKUP(TEXT(D17,"00"),Configurations!$B$5:$G$100,6,0),VLOOKUP(TEXT(RIGHT(D17,1),"0"),POSE_CSKN,3,0)) -> 12 | F17: =IF(WEEKDAY(C17)<>1,IF(E17>0,E17-IF(WEEKDAY(C17)=7,5,8),0),0) -> 0 | G17: =IF(OR(WEEKDAY(C17)=1, COUNTIF(Tableau_Pose_Cskn[Date],C17)>0),IF(E17>0,E17-IF(WEEKDAY(C17)=7,5,8),0),0) -> 4
B18: =TEXT(C18,"jjjj") -> lundi | C18: 45509 | D18: 997 | E18: =IF(LEN(TRIM(D18))=2,VLOOKUP(TEXT(D18,"00"),Configurations!$B$5:$G$100,6,0),VLOOKUP(TEXT(RIGHT(D18,1),"0"),POSE_CSKN,3,0)) -> 18 | F18: =IF(WEEKDAY(C18)<>1,IF(E18>0,E18-IF(WEEKDAY(C18)=7,5,8),0),0) -> 10 | G18: =IF(OR(WEEKDAY(C18)=1, COUNTIF(Tableau_Pose_Cskn[Date],C18)>0),IF(E18>0,E18-IF(WEEKDAY(C18)=7,5,8),0),0) -> 0
B19: =TEXT(C19,"jjjj") -> mardi | C19: 45510 | D19: 12 | E19: =IF(LEN(TRIM(D19))=2,VLOOKUP(TEXT(D19,"00"),Configurations!$B$5:$G$100,6,0),VLOOKUP(TEXT(RIGHT(D19,1),"0"),POSE_CSKN,3,0)) -> 0 | F19: =IF(WEEKDAY(C19)<>1,IF(E19>0,E19-IF(WEEKDAY(C19)=7,5,8),0),0) -> 0 | G19: =IF(OR(WEEKDAY(C19)=1, COUNTIF(Tableau_Pose_Cskn[Date],C19)>0),IF(E19>0,E19-IF(WEEKDAY(C19)=7,5,8),0),0) -> 0
B20: =TEXT(C20,"jjjj") -> mercredi | C20: 45511 | D20: 996 | E20: =IF(LEN(TRIM(D20))=2,VLOOKUP(TEXT(D20,"00"),Configurations!$B$5:$G$100,6,0),VLOOKUP(TEXT(RIGHT(D20,1),"0"),POSE_CSKN,3,0)) -> 12 | F20: =IF(WEEKDAY(C20)<>1,IF(E20>0,E20-IF(WEEKDAY(C20)=7,5,8),0),0) -> 4 | G20: =IF(OR(WEEKDAY(C20)=1, COUNTIF(Tableau_Pose_Cskn[Date],C20)>0),IF(E20>0,E20-IF(WEEKDAY(C20)=7,5,8),0),0) -> 0 | K20: 1.3 | L20: 1.6 | M20: 2
B21: =TEXT(C21,"jjjj") -> jeudi | C21: 45512 | D21: 996 | E21: =IF(LEN(TRIM(D21))=2,VLOOKUP(TEXT(D21,"00"),Configurations!$B$5:$G$100,6,0),VLOOKUP(TEXT(RIGHT(D21,1),"0"),POSE_CSKN,3,0)) -> 12 | F21: =IF(WEEKDAY(C21)<>1,IF(E21>0,E21-IF(WEEKDAY(C21)=7,5,8),0),0) -> 4 | G21: =IF(OR(WEEKDAY(C21)=1, COUNTIF(Tableau_Pose_Cskn[Date],C21)>0),IF(E21>0,E21-IF(WEEKDAY(C21)=7,5,8),0),0) -> 0 | J21: semaine 1 | K21: 6 | L21: 15 | M21: 0
B22: =TEXT(C22,"jjjj") -> vendredi | C22: 45513 | D22: 996 | E22: =IF(LEN(TRIM(D22))=2,VLOOKUP(TEXT(D22,"00"),Configurations!$B$5:$G$100,6,0),VLOOKUP(TEXT(RIGHT(D22,1),"0"),POSE_CSKN,3,0)) -> 12 | F22: =IF(WEEKDAY(C22)<>1,IF(E22>0,E22-IF(WEEKDAY(C22)=7,5,8),0),0) -> 4 | G22: =IF(OR(WEEKDAY(C22)=1, COUNTIF(Tableau_Pose_Cskn[Date],C22)>0),IF(E22>0,E22-IF(WEEKDAY(C22)=7,5,8),0),0) -> 0 | J22: semaine 2 | K22: 6 | L22: 27 | M22: 0
B23: =TEXT(C23,"jjjj") -> samedi | C23: 45514 | D23: 996 | E23: =IF(LEN(TRIM(D23))=2,VLOOKUP(TEXT(D23,"00"),Configurations!$B$5:$G$100,6,0),VLOOKUP(TEXT(RIGHT(D23,1),"0"),POSE_CSKN,3,0)) -> 12 | F23: =IF(WEEKDAY(C23)<>1,IF(E23>0,E23-IF(WEEKDAY(C23)=7,5,8),0),0) -> 7 | G23: =IF(OR(WEEKDAY(C23)=1, COUNTIF(Tableau_Pose_Cskn[Date],C23)>0),IF(E23>0,E23-IF(WEEKDAY(C23)=7,5,8),0),0) -> 0 | J23: semaine 3 | K23: 6 | L23: 15 | M23: 0
B24: =TEXT(C24,"jjjj") -> dimanche | C24: 45515 | D24: 996 | E24: =IF(LEN(TRIM(D24))=2,VLOOKUP(TEXT(D24,"00"),Configurations!$B$5:$G$100,6,0),VLOOKUP(TEXT(RIGHT(D24,1),"0"),POSE_CSKN,3,0)) -> 12 | F24: =IF(WEEKDAY(C24)<>1,IF(E24>0,E24-IF(WEEKDAY(C24)=7,5,8),0),0) -> 0 | G24: =IF(OR(WEEKDAY(C24)=1, COUNTIF(Tableau_Pose_Cskn[Date],C24)>0),IF(E24>0,E24-IF(WEEKDAY(C24)=7,5,8),0),0) -> 4 | J24: semaine 4 | K24: 6 | L24: 15 | M24: 0
B25: =TEXT(C25,"jjjj") -> lundi | C25: 45516 | D25: 997 | E25: =IF(LEN(TRIM(D25))=2,VLOOKUP(TEXT(D25,"00"),Configurations!$B$5:$G$100,6,0),VLOOKUP(TEXT(RIGHT(D25,1),"0"),POSE_CSKN,3,0)) -> 18 | F25: =IF(WEEKDAY(C25)<>1,IF(E25>0,E25-IF(WEEKDAY(C25)=7,5,8),0),0) -> 10 | G25: =IF(OR(WEEKDAY(C25)=1, COUNTIF(Tableau_Pose_Cskn[Date],C25)>0),IF(E25>0,E25-IF(WEEKDAY(C25)=7,5,8),0),0) -> 0 | J25: semaine 5 | K25: 6 | L25: 4 | M25: 0
B26: =TEXT(C26,"jjjj") -> mardi | C26: 45517 | D26: 998 | E26: =IF(LEN(TRIM(D26))=2,VLOOKUP(TEXT(D26,"00"),Configurations!$B$5:$G$100,6,0),VLOOKUP(TEXT(RIGHT(D26,1),"0"),POSE_CSKN,3,0)) -> 12 | F26: =IF(WEEKDAY(C26)<>1,IF(E26>0,E26-IF(WEEKDAY(C26)=7,5,8),0),0) -> 4 | G26: =IF(OR(WEEKDAY(C26)=1, COUNTIF(Tableau_Pose_Cskn[Date],C26)>0),IF(E26>0,E26-IF(WEEKDAY(C26)=7,5,8),0),0) -> 0 | J26: HS Jr non ouvré | K26: 0 | L26: 0 | M26: 24
B27: =TEXT(C27,"jjjj") -> mercredi | C27: 45518 | D27: 998 | E27: =IF(LEN(TRIM(D27))=2,VLOOKUP(TEXT(D27,"00"),Configurations!$B$5:$G$100,6,0),VLOOKUP(TEXT(RIGHT(D27,1),"0"),POSE_CSKN,3,0)) -> 12 | F27: =IF(WEEKDAY(C27)<>1,IF(E27>0,E27-IF(WEEKDAY(C27)=7,5,8),0),0) -> 4 | G27: =IF(OR(WEEKDAY(C27)=1, COUNTIF(Tableau_Pose_Cskn[Date],C27)>0),IF(E27>0,E27-IF(WEEKDAY(C27)=7,5,8),0),0) -> 0
B28: =TEXT(C28,"jjjj") -> jeudi | C28: 45519 | D28: 998 | E28: =IF(LEN(TRIM(D28))=2,VLOOKUP(TEXT(D28,"00"),Configurations!$B$5:$G$100,6,0),VLOOKUP(TEXT(RIGHT(D28,1),"0"),POSE_CSKN,3,0)) -> 12 | F28: =IF(WEEKDAY(C28)<>1,IF(E28>0,E28-IF(WEEKDAY(C28)=7,5,8),0),0) -> 4 | G28: =IF(OR(WEEKDAY(C28)=1, COUNTIF(Tableau_Pose_Cskn[Date],C28)>0),IF(E28>0,E28-IF(WEEKDAY(C28)=7,5,8),0),0) -> 0
B29: =TEXT(C29,"jjjj") -> vendredi | C29: 45520 | D29: 998 | E29: =IF(LEN(TRIM(D29))=2,VLOOKUP(TEXT(D29,"00"),Configurations!$B$5:$G$100,6,0),VLOOKUP(TEXT(RIGHT(D29,1),"0"),POSE_CSKN,3,0)) -> 12 | F29: =IF(WEEKDAY(C29)<>1,IF(E29>0,E29-IF(WEEKDAY(C29)=7,5,8),0),0) -> 4 | G29: =IF(OR(WEEKDAY(C29)=1, COUNTIF(Tableau_Pose_Cskn[Date],C29)>0),IF(E29>0,E29-IF(WEEKDAY(C29)=7,5,8),0),0) -> 0
B30: =TEXT(C30,"jjjj") -> samedi | C30: 45521 | D30: 12 | E30: =IF(LEN(TRIM(D30))=2,VLOOKUP(TEXT(D30,"00"),Configurations!$B$5:$G$100,6,0),VLOOKUP(TEXT(RIGHT(D30,1),"0"),POSE_CSKN,3,0)) -> 0 | F30: =IF(WEEKDAY(C30)<>1,IF(E30>0,E30-IF(WEEKDAY(C30)=7,5,8),0),0) -> 0 | G30: =IF(OR(WEEKDAY(C30)=1, COUNTIF(Tableau_Pose_Cskn[Date],C30)>0),IF(E30>0,E30-IF(WEEKDAY(C30)=7,5,8),0),0) -> 0
B31: =TEXT(C31,"jjjj") -> dimanche | C31: 45522 | D31: 998 | E31: =IF(LEN(TRIM(D31))=2,VLOOKUP(TEXT(D31,"00"),Configurations!$B$5:$G$100,6,0),VLOOKUP(TEXT(RIGHT(D31,1),"0"),POSE_CSKN,3,0)) -> 12 | F31: =IF(WEEKDAY(C31)<>1,IF(E31>0,E31-IF(WEEKDAY(C31)=7,5,8),0),0) -> 0 | G31: =IF(OR(WEEKDAY(C31)=1, COUNTIF(Tableau_Pose_Cskn[Date],C31)>0),IF(E31>0,E31-IF(WEEKDAY(C31)=7,5,8),0),0) -> 4
B32: =TEXT(C32,"jjjj") -> lundi | C32: 45523 | D32: 997 | E32: =IF(LEN(TRIM(D32))=2,VLOOKUP(TEXT(D32,"00"),Configurations!$B$5:$G$100,6,0),VLOOKUP(TEXT(RIGHT(D32,1),"0"),POSE_CSKN,3,0)) -> 18 | F32: =IF(WEEKDAY(C32)<>1,IF(E32>0,E32-IF(WEEKDAY(C32)=7,5,8),0),0) -> 10 | G32: =IF(OR(WEEKDAY(C32)=1, COUNTIF(Tableau_Pose_Cskn[Date],C32)>0),IF(E32>0,E32-IF(WEEKDAY(C32)=7,5,8),0),0) -> 0
B33: =TEXT(C33,"jjjj") -> mardi | C33: 45524 | D33: 12 | E33: =IF(LEN(TRIM(D33))=2,VLOOKUP(TEXT(D33,"00"),Configurations!$B$5:$G$100,6,0),VLOOKUP(TEXT(RIGHT(D33,1),"0"),POSE_CSKN,3,0)) -> 0 | F33: =IF(WEEKDAY(C33)<>1,IF(E33>0,E33-IF(WEEKDAY(C33)=7,5,8),0),0) -> 0 | G33: =IF(OR(WEEKDAY(C33)=1, COUNTIF(Tableau_Pose_Cskn[Date],C33)>0),IF(E33>0,E33-IF(WEEKDAY(C33)=7,5,8),0),0) -> 0
E34: =SUM(E3:E33) -> 354 | F34: =SUM(F3:F33) -> 135 | G34: =SUM(G3:G33) -> 24

Sheet Configurations
C3: POINTAGE | K3: POSE
B5: CODE | C5: LIBELLE | D5: Observation | E5: TACHE | F5: PRESENCE | G5: Heures Prestées | K5: CODE | L5: LIBELLE | M5: Heures Prestées
B6: 01 | C6: ABSENCE AUTORISEE NON A PAYER | D6: Pas de présence physique | E6: 5 | F6: 0 | G6: 0 | K6: 0 | L6: EQUIPE JOUR | M6: 8
B7: 02 | C7: ABSENCE NON AUTORISEE | D7: Pas de présence physique | E7: 0 | F7: 0 | G7: 0 | K7: 1 | L7: POSE 1 DE 8 H (6 - 14 OU 7-15) | M7: 8
B8: 03 | C8: SANS POINTAGE | D8: Pas de présence physique | E8: 8 | F8: 0 | G8: 0 | K8: 2 | L8: POSE 2 DE 8 H (14--22 OU 15-23 | M8: 8
B9: 04 | C9: CARTE RETENUE | D9: Pas de présence physique | E9: 0 | F9: 0 | G9: 0 | K9: 3 | L9: POSE 3 DE 8 H (22-6 OU 23-7) | M9: 8
B10: 05 | C10: CONGE DE CIRCONSTANCE | D10: Pas de présence physique | E10: 11 | F10: 0 | G10: 0 | K10: 6 | L10: POSE 1 DE 12H ( 6-18) | M10: 12
B11: 06 | C11: SUSPENSION/CONVOCATION | D11: Pas de présence physique | E11: 15 | F11: 0 | G11: 0 | K11: 7 | L11: CHANGEMENT DE POSE 6-18 / 18-6 | M11: 18
B12: 07 | C12: ACCID. TRAV./INCAPACITE CADRE | D12: Pas de présence physique | E12: 0 | F12: 0 | G12: 0 | K12: 8 | L12: POSE 2 DE 12H (18-6) | M12: 12
B13: 08 | C13: MALADIE/REPOS MEDICAL/MATERNITE | D13: Pas de présence physique | E13: 0 | F13: 0 | G13: 0 | K13: N | L13: NON POSE | M13: 8
B14: 09 | C14: SANCTION | D14: Pas de présence physique | E14: 8 | F14: 0 | G14: 0
B15: 10 | C15: SUSPENSION CONTRAT | D15: Pas de présence physique | E15: 0 | F15: 0 | G15: 0
B16: 11 | C16: JOURNEE FERIEE NON PRESTEE | D16: Pas de présence physique | E16: 6 | F16: 0 | G16: 0
B17: 12 | C17: REPOS PAYE | D17: Pas de présence physique | E17: 0 | F17: 0 | G17: 0
B18: 13 | C18: GARDE A DOMICILE | D18: Pas de présence physique | E18: 45 | F18: 0 | G18: 0
B19: 14 | C19: POINTAGE EXCEPTIONNELLE | D19: Pas de présence physique | E19: 0 | F19: 0 | G19: 0
B20: 15 | C20: CESSATION DE TRAVAIL | D20: Pas de présence physique | E20: 0 | F20: 0 | G20: 0
B21: 20 | C21: COUPE FABRICATION | D21: Présence physique | E21: 1 | F21: 1
B22: 21 | C22: COUPE-FEU RECOLTE | D22: Présence physique | E22: 1 | F22: 1 | G22: 8
B23: 22 | C23: COUPE DEGAGEMENT | D23: Présence physique | E23: 1 | F23: 1 | G23: 8
B24: 23 | C24: COUPE-FEU EXTERIEUR | D24: Présence physique | E24: 1 | F24: 1 | G24: 8
B25: 24 | C25: GLANAGE MACHINE | D25: Présence physique | E25: 0 | F25: 1 | G25: 8
B26: 25 | C26: GLANAGE SUR CHAMPS | D26: Présence physique | E26: 1 | F26: 1 | G26: 8
B27: 26 | C27: GLANAGE ROUTE-RAIL | D27: Présence physique | E27: 0 | F27: 1 | G27: 8
B28: 27 | C28: CHARGEMENT ROUTE-RAIL | D28: Présence physique | E28: 1 | F28: 1 | G28: 8
B29: 28 | C29: CHARG. MANUEL + EVACUATION | D29: Présence physique | E29: 1 | F29: 1 | G29: 8
B30: 29 | C30: PREPARATION CARREAUX | D30: Présence physique | E30: 1 | F30: 1 | G30: 8
B31: 30 | C31: ECHANTILLONNAGE | D31: Présence physique | E31: 0 | F31: 1 | G31: 8
B32: 31 | C32: AIDES WATER-TANK | D32: Présence physique | E32: 0 | F32: 1 | G32: 8
B33: 32 | C33: CHAUFFEUR TRACTEUR RENTREE CANNES | D33: Présence physique | E33: 0 | F33: 1 | G33: 8
... B100: 99 | C100: AUTRES TRAVAUX EXTERIEURS | D100: Présence physique | E100: 0 | F100: 1 | G100: 8
